Workbook

Sheet Arhive
A1: п/п | B1: =INDEX($H1:$IV1,1,COUNTA($H1:$IV1)+2) -> 2025-10-01 | C1: нынешние показания | D1: предыдущеий месяц | E1: задолженность (актуальная) | F1: учтена оплата (актуальная) | H1: 2022-12-01 | I1: 2023-01-01 | J1: 2023-02-01 | K1: 2023-03-01 | L1: 2023-04-01 | M1: 2023-05-01 | N1: 2023-06-01 | O1: 2023-07-01 | P1: 2023-08-01 | Q1: 2023-09-01 | R1: 2023-10-01 | S1: Смена счетчиков | U1: 2023-11-01 | V1: 2023-12-01 | W1: 2024-01-01 | X1: 2024-02-01 | Y1: 2024-03-01 | Z1: 2024-04-01 | AA1: 2024-05-01 | AB1: 2024-06-01 | AC1: 2024-07-01 | AD1: 2024-08-01 | AE1: 2024-09-01 | AF1: 2024-10-01 | AG1: 2024-11-01 | AH1: 2024-12-01 | AI1: 2025-01-01 | AJ1: 2025-02-01 | AK1: 2025-03-01 | AL1: 2025-04-01 | AM1: смена счетчика | AO1: 2025-05-01 | AP1: 2025-06-01 | AQ1: 2025-07-01 | AR1: 2025-08-01 | AS1: 2025-09-01 | AT1: 2025-10-01
A2: 1 | B2: Гаценко НатГаврил | C2: =INDEX($H2:$IV2,1,COUNTA($H2:$IV2)) -> 683.9 | D2: =INDEX($H2:$IV2,1,COUNTA($H2:$IV2)-1) -> 678.15 | E2: -282.57 | F2: 500 | G2: 21 | H2: 338.55 | I2: 353.81 | J2: 371.01 | K2: 404.91 | L2: 431.05 | M2: 454.17 | N2: 474.45 | O2: 484.96 | P2: 486.6 | Q2: 497.41 | R2: 508.22 | S2: 0 | T2: 0.81 | U2: 29.18 | V2: 35.45 | W2: 47.05 | X2: 86.77 | Y2: 120.34 | Z2: 170.56 | AA2: 203.33 | AB2: 220.04 | AC2: 230.86 | AD2: 237.31 | AE2: 245.04 | AF2: 256.69 | AG2: 294.48 | AH2: 340.12 | AI2: 376.49 | AJ2: 410.87 | AK2: 433.59 | AL2: 458.7 | AM2: 458.7 | AN2: 458.7 | AO2: 484.49 | AP2: 526.91 | AQ2: 591.19 | AR2: 656.49 | AS2: 678.15 | AT2: 683.9
A3: 1 | B3: Гаценко НатГаврил | C3: =INDEX($H3:$IV3,1,COUNTA($H3:$IV3)) -> 105.13 | D3: =INDEX($H3:$IV3,1,COUNTA($H3:$IV3)-1) -> 104.69 | G3: 21 | H3: 98.38 | I3: 101.39 | J3: 102.69 | K3: 102.69 | L3: 102.85 | M3: 106.9 | N3: 112.35 | O3: 116.45 | P3: 116.98 | Q3: 120.34 | R3: 123.7 | S3: 0 | T3: 7.99 | U3: 10.23 | V3: 10.82 | W3: 11.13 | X3: 13.99 | Y3: 20.29 | Z3: 30.15 | AA3: 37.34 | AB3: 42 | AC3: 46.72 | AD3: 47.89 | AE3: 49.57 | AF3: 51.97 | AG3: 52.61 | AH3: 55.15 | AI3: 58.52 | AJ3: 68.23 | AK3: 71.37 | AL3: 72.66 | AM3: 72.66 | AN3: 72.66 | AO3: 80.38 | AP3: 91.25 | AQ3: 96.34 | AR3: 102.97 | AS3: 104.69 | AT3: 105.13
A4: 2 | B4: Дикарев АлексейАнат | C4: =INDEX($H4:$IV4,1,COUNTA($H4:$IV4)) -> 0 | D4: =INDEX($H4:$IV4,1,COUNTA($H4:$IV4)-1) -> 0 | E4: 0 | G4: 54 | H4: 20898.02 | I4: 21233.78 | J4: 21253 | K4: 21929.65 | L4: 22274 | M4: 22624.81 | N4: 22943 | O4: 23333 | P4: 23751 | Q4: 24146 | R4: 24542 | S4: 24542 | T4: 24542 | U4: 24950 | V4: 25436 | W4: 25934 | X4: 26387 | Y4: 26771.2 | Z4: 27190 | AA4: 27628 | AB4: 28103 | AC4: 28711 | AD4: 0 | AE4: 0 | AF4: 0 | AG4: 0 | AH4: 0 | AI4: 0 | AJ4: 0 | AK4: 0 | AL4: 0 | AM4: 0 | AN4: 0 | AO4: 0 | AP4: 0 | AQ4: 0 | AR4: 0 | AS4: 0 | AT4: 0
A5: 2 | B5: Дикарев АлексейАнат | C5: =INDEX($H5:$IV5,1,COUNTA($H5:$IV5)) -> 0 | D5: =INDEX($H5:$IV5,1,COUNTA($H5:$IV5)-1) -> 0 | G5: 54 | H5: 9353.16 | I5: 9486.78 | J5: 9495 | K5: 9764.99 | L5: 9905 | M5: 10054.27 | N5: 10214 | O5: 10430 | P5: 10627 | Q5: 10859 | R5: 11046 | S5: 11046 | T5: 11046 | U5: 11231 | V5: 11423 | W5: 11622 | X5: 11813 | Y5: 11973.43 | Z5: 12181 | AA5: 12374.55 | AB5: 12610 | AC5: 12899 | AD5: 0 | AE5: 0 | AF5: 0 | AG5: 0 | AH5: 0 | AI5: 0 | AJ5: 0 | AK5: 0 | AL5: 0 | AM5: 0 | AN5: 0 | AO5: 0 | AP5: 0 | AQ5: 0 | AR5: 0 | AS5: 0 | AT5: 0
A6: 3 | B6: Дмитриев Ал-р Вахтанг | C6: =INDEX($H6:$IV6,1,COUNTA($H6:$IV6)) -> 23549.72 | D6: =INDEX($H6:$IV6,1,COUNTA($H6:$IV6)-1) -> 23280.28 | E6: 8160.23 | G6: 51 | H6: 12300.97 | I6: 12642.16 | J6: 12921.49 | K6: 13089.08 | L6: 13338.92 | M6: 13556.15 | N6: 13740.64 | O6: 14024.3 | P6: 14584.83 | Q6: 14902.39 | R6: 15106.31 | S6: 15106.31 | T6: 15106.31 | U6: 15367.76 | V6: 15675.84 | W6: 16014.9 | X6: 16307.53 | Y6: 16557.35 | Z6: 16819.24 | AA6: 17043.03 | AB6: 17388.44 | AC6: 17995.66 | AD6: 18472.65 | AE6: 18854.57 | AF6: 19107.09 | AG6: 19439.96 | AH6: 19855.93 | AI6: 20201.19 | AJ6: 20659.47 | AK6: 20981.42 | AL6: 21322.31 | AM6: 21322.31 | AN6: 21322.31 | AO6: 21596.05 | AP6: 21859.96 | AQ6: 22324.48 | AR6: 23008.34 | AS6: 23280.28 | AT6: 23549.72
A7: 3 | B7: Дмитриев Ал-рВахтанг | C7: =INDEX($H7:$IV7,1,COUNTA($H7:$IV7)) -> 8771.92 | D7: =INDEX($H7:$IV7,1,COUNTA($H7:$IV7)-1) -> 8584.14 | G7: 51 | H7: 3672.18 | I7: 3808.71 | J7: 3935.03 | K7: 4004.78 | L7: 4100.94 | M7: 4194.75 | N7: 4262.86 | O7: 4319.12 | P7: 4448.78 | Q7: 4541.68 | R7: 4618.31 | S7: 4618.31 | T7: 4618.31 | U7: 4711.29 | V7: 4821.18 | W7: 4937.65 | X7: 5046.26 | Y7: 5144.85 | Z7: 5243.09 | AA7: 5329.02 | AB7: 5410.87 | AC7: 5560.6 | AD7: 5712.29 | AE7: 5834.71 | AF7: 6054.29 | AG7: 6342.24 | AH7: 6594.31 | AI7: 6788.58 | AJ7: 7051.98 | AK7: 7290.51 | AL7: 7554.16 | AM7: 7554.16 | AN7: 7554.16 | AO7: 7724.31 | AP7: 7930.48 | AQ7: 8161.39 | AR7: 8440.04 | AS7: 8584.14 | AT7: 8771.92
A8: 4 | B8: Егоров ЕвгЮрьев | C8: =INDEX($H8:$IV8,1,COUNTA($H8:$IV8)) -> 20395.7 | D8: =INDEX($H8:$IV8,1,COUNTA($H8:$IV8)-1) -> 20213.43 | E8: 2391.64 | G8: 35 | H8: 14583.37 | I8: 14820.84 | J8: 15016.04 | K8: 15188.39 | L8: 15365.43 | M8: 15544.14 | N8: 15711.87 | O8: 15862.24 | P8: 15982.6 | Q8: 16118.65 | R8: 16278.21 | S8: 16278.21 | T8: 16278.21 | U8: 16451.17 | V8: 16648.91 | W8: 16893.39 | X8: 17069.71 | Y8: 17242.78 | Z8: 17408.32 | AA8: 17587.68 | AB8: 17726.93 | AC8: 17853.71 | AD8: 17972.77 | AE8: 18108.1 | AF8: 18269.38 | AG8: 18450.49 | AH8: 18672 | AI8: 18812.9 | AJ8: 19102.12 | AK8: 19289.66 | AL8: 19508.66 | AM8: 19508.66 | AN8: 19508.66 | AO8: 19693.78 | AP8: 19835.69 | AQ8: 19952.24 | AR8: 20081.19 | AS8: 20213.43 | AT8: 20395.7
A9: 4 | B9: Егоров ЕвгЮрьев | C9: =INDEX($H9:$IV9,1,COUNTA($H9:$IV9)) -> 5911.38 | D9: =INDEX($H9:$IV9,1,COUNTA($H9:$IV9)-1) -> 5842.58 | G9: 35 | H9: 3782.01 | I9: 3865.29 | J9: 3945.07 | K9: 4012.05 | L9: 4079.6 | M9: 4153.63 | N9: 4229.21 | O9: 4299.75 | P9: 4354.47 | Q9: 4408.14 | R9: 4464.65 | S9: 4464.65 | T9: 4464.65 | U9: 4528.13 | V9: 4590.25 | W9: 4671.4 | X9: 4729.33 | Y9: 4784.46 | Z9: 4845.91 | AA9: 4917.94 | AB9: 4971.59 | AC9: 5019.15 | AD9: 5072.28 | AE9: 5130.12 | AF9: 5186.48 | AG9: 5246.31 | AH9: 5307.85 | AI9: 5361.98 | AJ9: 5449.33 | AK9: 5514.05 | AL9: 5580.08 | AM9: 5580.08 | AN9: 5580.08 | AO9: 5645.8 | AP9: 5713.01 | AQ9: 5756.92 | AR9: 5801.23 | AS9: 5842.58 | AT9: 5911.38
A10: 5 | B10: Ефимов Вл-р Васил | C10: =INDEX($H10:$IV10,1,COUNTA($H10:$IV10)) -> 2980.63 | D10: =INDEX($H10:$IV10,1,COUNTA($H10:$IV10)-1) -> 2953.62 | E10: -299.95 | G10: 46 | H10: 1897.12 | I10: 1928.24 | J10: 1954.73 | K10: 1973.92 | L10: 2000.46 | M10: 2059.64 | N10: 2063.01 | O10: 2099.47 | P10: 2140.34 | Q10: 2184.75 | R10: 2222.57 | S10: 2222.57 | T10: 2222.57 | U10: 2252.53 | V10: 2279.17 | W10: 2306.81 | X10: 2337.17 | Y10: 2362.02 | Z10: 2393.01 | AA10: 2416.62 | AB10: 2446.48 | AC10: 2484.19 | AD10: 2525.88 | AE10: 2572.82 | AF10: 2607.41 | AG10: 2637.27 | AH10: 2667.09 | AI10: 2692.92 | AJ10: 2716.9 | AK10: 2742.9 | AL10: 2779.58 | AM10: 2779.58 | AN10: 2779.58 | AO10: 2809.46 | AP10: 2848.37 | AQ10: 2888.9 | AR10: 2927.85 | AS10: 2953.62 | AT10: 2980.63
A11: 5 | B11: Ефимов Вл-р Васил | C11: =INDEX($H11:$IV11,1,COUNTA($H11:$IV11)) -> 561.35 | D11: =INDEX($H11:$IV11,1,COUNTA($H11:$IV11)-1) -> 556.36 | G11: 46 | H11: 351.86 | I11: 356.8 | J11: 360.74 | K11: 364.37 | L11: 368.63 | M11: 373.7 | N11: 381.02 | O11: 389.32 | P11: 397.93 | Q11: 406.39 | R11: 413.94 | S11: 413.94 | T11: 413.94 | U11: 419.55 | V11: 423.45 | W11: 426.94 | X11: 429.94 | Y11: 432.99 | Z11: 437.85 | AA11: 442.66 | AB11: 449.91 | AC11: 458.6 | AD11: 467.8 | AE11: 477.13 | AF11: 485.42 | AG11: 491.82 | AH11: 496.98 | AI11: 501.62 | AJ11: 504.98 | AK11: 509.12 | AL11: 515.53 | AM11: 515.53 | AN11: 515.53 | AO11: 523.18 | AP11: 531.25 | AQ11: 540.41 | AR11: 549.35 | AS11: 556.36 | AT11: 561.35
A12: 6 | B12: Заруба ЛюдмСерг | C12: =INDEX($H12:$IV12,1,COUNTA($H12:$IV12)) -> 10011.4 | D12: =INDEX($H12:$IV12,1,COUNTA($H12:$IV12)-1) -> 9822.8 | E12: -1452.49 | G12: 17 | H12: 955.8 | I12: 1762.8 | J12: 2829.7 | K12: 3702.8 | L12: 4335.6 | M12: 4710.2 | N12: 4796 | O12: 4875.7 | P12: 4955.8 | Q12: 5033.5 | R12: 5149.9 | S12: 5149.9 | T12: 5149.9 | U12: 5311.2 | V12: 5805 | W12: 6209.3 | X12: 6492.9 | Y12: 6972 | Z12: 7145.3 | AA12: 7214.4 | AB12: 7287 | AC12: 7378.2 | AD12: 7465.5 | AE12: 7552 | AF12: 7647.4 | AG12: 7884.5 | AH12: 8305.9 | AI12: 8847.9 | AJ12: 9477 | AK12: 9477.4 | AL12: 9477.8 | AM12: 9477.8 | AN12: 9477.8 | AO12: 9564.1 | AP12: 9602.5 | AQ12: 9664.9 | AR12: 9758 | AS12: 9822.8 | AT12: 10011.4
A13: 7 | B13: Зырянов ДмитрНик | C13: =INDEX($H13:$IV13,1,COUNTA($H13:$IV13)) -> 20682.76 | D13: =INDEX($H13:$IV13,1,COUNTA($H13:$IV13)-1) -> 20464.02 | E13: 1079.56 | F13: 1081.4 | G13: 3 | H13: 13457.47 | I13: 13701.58 | J13: 13953.08 | K13: 14155.46 | L13: 14396.65 | M13: 14586.26 | N13: 14756.9 | O13: 15068.15 | P13: 15434.42 | Q13: 15662.68 | R13: 15819.18 | S13: 15819.18 | T13: 15819.18 | U13: 16002.92 | V13: 16170.99 | W13: 16375.25 | X13: 16627.33 | Y13: 16839.71 | Z13: 17079.59 | AA13: 17292.14 | AB13: 17533.05 | AC13: 17906.18 | AD13: 18189.56 | AE13: 18392.07 | AF13: 18580.19 | AG13: 18738.11 | AH13: 18942.37 | AI13: 19159.2 | AJ13: 19367.9 | AK13: 19564.99 | AL13: 19757.06 | AM13: 19757.06 | AN13: 19757.06 | AO13: 19925.23 | AP13: 20067.62 | AQ13: 20183.98 | AR13: 20298.32 | AS13: 20464.02 | AT13: 20682.76
A14: 7 | B14: Зырянов ДмитрНик | C14: =INDEX($H14:$IV14,1,COUNTA($H14:$IV14)) -> 6661.37 | D14: =INDEX($H14:$IV14,1,COUNTA($H14:$IV14)-1) -> 6589.22 | G14: 3 | H14: 4336.7 | I14: 4414.1 | J14: 4485.49 | K14: 4549.62 | L14: 4618.24 | M14: 4682.97 | N14: 4737.18 | O14: 4800.45 | P14: 4868.36 | Q14: 4928.98 | R14: 4986.69 | S14: 4986.69 | T14: 4986.69 | U14: 5058.52 | V14: 5122.1 | W14: 5189.26 | X14: 5265.23 | Y14: 5347.31 | Z14: 5432.23 | AA14: 5500.8 | AB14: 5563.4 | AC14: 5644.32 | AD14: 5740.73 | AE14: 5801.6 | AF14: 5868.41 | AG14: 5931.26 | AH14: 6002.81 | AI14: 6073.14 | AJ14: 6148.29 | AK14: 6212.95 | AL14: 6284.21 | AM14: 6284.21 | AN14: 6284.21 | AO14: 6353.38 | AP14: 6413.87 | AQ14: 6467.34 | AR14: 6523.15 | AS14: 6589.22 | AT14: 6661.37
A15: 8 | B15: Кавун А.И. | C15: =INDEX($H15:$IV15,1,COUNTA($H15:$IV15)) -> 12116.96 | D15: =INDEX($H15:$IV15,1,COUNTA($H15:$IV15)-1) -> 11948.97 | E15: 1643.12 | F15: 6643 | G15: 44 | H15: 4912.14 | I15: 5131.2 | J15: 5334.48 | K15: 5519.42 | L15: 5718.16 | M15: 5865.55 | N15: 5975.72 | O15: 6108.8 | P15: 6240.69 | Q15: 6366.34 | R15: 6473.55 | S15: 6473.55 | T15: 6473.55 | U15: 6617.2 | V15: 6834.47 | W15: 7032.56 | X15: 7228.87 | Y15: 7426.07 | Z15: 7608.28 | AA15: 7732.58 | AB15: 7835.33 | AC15: 7943.8 | AD15: 8055.64 | AE15: 8221.4 | AF15: 8345.84 | AG15: 8555.1 | AH15: 8787.21 | AI15: 9007.21 | AJ15: 9237.21 | AK15: 9450.21 | AL15: 9940.02 | AM15: 9940.02 | AN15: 9940.02 | AO15: 10293.22 | AP15: 10598.88 | AQ15: 10989.03 | AR15: 11498.97 | AS15: 11948.97 | AT15: 12116.96
A16: 8 | B16: Кавун А.И. | C16: =INDEX($H16:$IV16,1,COUNTA($H16:$IV16)) -> 5784.35 | D16: =INDEX($H16:$IV16,1,COUNTA($H16:$IV16)-1) -> 5731.93 | G16: 44 | H16: 2060.48 | I16: 2173.22 | J16: 2274.91 | K16: 2367.93 | L16: 2482.27 | M16: 2577.45 | N16: 2659.02 | O16: 2732.84 | P16: 2792.08 | Q16: 2873.12 | R16: 2958.85 | S16: 2958.85 | T16: 2958.85 | U16: 3035.76 | V16: 3139.49 | W16: 3236.26 | X16: 3329.31 | Y16: 3424.22 | Z16: 3545.33 | AA16: 3644.66 | AB16: 3743.93 | AC16: 3837.48 | AD16: 3937.48 | AE16: 4013.55 | AF16: 4082.01 | AG16: 4190.5 | AH16: 4302.51 | AI16: 4411.31 | AJ16: 4511.31 | AK16: 4615.31 | AL16: 4880.92 | AM16: 4880.92 | AN16: 4880.92 | AO16: 5110.93 | AP16: 5275.01 | AQ16: 5400.08 | AR16: 5581.93 | AS16: 5731.93 | AT16: 5784.35
A17: 9 | B17: Калашников В.В. | C17: =INDEX($H17:$IV17,1,COUNTA($H17:$IV17)) -> 2152.36 | D17: =INDEX($H17:$IV17,1,COUNTA($H17:$IV17)-1) -> 2130 | E17: 529.91 | G17: 22 | H17: 1042.04 | I17: 1096.97 | J17: 1141.71 | K17: 1174.95 | L17: 1206.7 | M17: 1235.5 | N17: 1261.62 | O17: 1287.2 | P17: 1316.13 | Q17: 1342.23 | R17: 1378.55 | S17: 1378.55 | T17: 1378.55 | U17: 1421.2 | V17: 1468.29 | W17: 1515.71 | X17: 1555.28 | Y17: 1588.13 | Z17: 1619.36 | AA17: 1645.08 | AB17: 1668.92 | AC17: 1692.08 | AD17: 1718.63 | AE17: 1750.55 | AF17: 1786.45 | AG17: 1828.61 | AH17: 1877.96 | AI17: 1924.07 | AJ17: 1966.52 | AK17: 1996.68 | AL17: 2026.74 | AM17: 2026.74 | AN17: 2026.74 | AO17: 2052.4 | AP17: 2075.08 | AQ17: 2096.93 | AR17: 2122.77 | AS17: 2130 | AT17: 2152.36
A18: 9 | B18: Калашников В.В. | C18: =INDEX($H18:$IV18,1,COUNTA($H18:$IV18)) -> 2710.89 | D18: =INDEX($H18:$IV18,1,COUNTA($H18:$IV18)-1) -> 2698.33 | G18: 22 | H18: 1287.49 | I18: 1344.12 | J18: 1397.79 | K18: 1445.27 | L18: 1491.56 | M18: 1534.34 | N18: 1575.48 | O18: 1616.72 | P18: 1657.92 | Q18: 1692.21 | R18: 1737.85 | S18: 1737.85 | T18: 1737.85 | U18: 1785.51 | V18: 1832.77 | W18: 1881.48 | X18: 1928.49 | Y18: 1974.55 | Z18: 2019.18 | AA18: 2056.89 | AB18: 2093.67 | AC18: 2129.7 | AD18: 2169.97 | AE18: 2213.73 | AF18: 2259.51 | AG18: 2306.72 | AH18: 2355.83 | AI18: 2403.48 | AJ18: 2453.97 | AK18: 2495.77 | AL18: 2537.98 | AM18: 2537.98 | AN18: 2537.98 | AO18: 2574.29 | AP18: 2607.41 | AQ18: 2639.56 | AR18: 2676.55 | AS18: 2698.33 | AT18: 2710.89
A19: 10 | B19: Картира Я.А. | C19: =INDEX($H19:$IV19,1,COUNTA($H19:$IV19)) -> 5042.34 | D19: =INDEX($H19:$IV19,1,COUNTA($H19:$IV19)-1) -> 4913.53 | E19: 1205.5 | G19: 8 | H19: 2073.32 | I19: 2133.49 | J19: 2166.23 | K19: 2188.99 | L19: 2224.41 | M19: 2260.89 | N19: 2312.26 | O19: 2366.91 | P19: 2425.36 | Q19: 2466.91 | R19: 2525.26 | S19: 2525.26 | T19: 2525.26 | U19: 2585.3 | V19: 2683.55 | W19: 2828.29 | X19: 2935.9 | Y19: 3051.29 | Z19: 3138.82 | AA19: 3180.51 | AB19: 3227.3 | AC19: 3278.61 | AD19: 3329.61 | AE19: 3381.89 | AF19: 3443.8 | AG19: 3576.41 | AH19: 3717.41 | AI19: 3826.14 | AJ19: 3938.1 | AK19: 4042.58 | AL19: 4149.67 | AM19: 4149.67 | AN19: 4149.67 | AO19: 4277.19 | AP19: 4400.51 | AQ19: 4545.66 | AR19: 4731.05 | AS19: 4913.53 | AT19: 5042.34
A20: 10 | B20: Картира Я.А. | C20: =INDEX($H20:$IV20,1,COUNTA($H20:$IV20)) -> 2208.45 | D20: =INDEX($H20:$IV20,1,COUNTA($H20:$IV20)-1) -> 2138.88 | G20: 8 | H20: 849.33 | I20: 869.44 | J20: 888.15 | K20: 905.25 | L20: 923.26 | M20: 945.65 | N20: 968.92 | O20: 987.67 | P20: 1007.37 | Q20: 1032.23 | R20: 1057.8 | S20: 1057.8 | T20: 1057.8 | U20: 1084.72 | V20: 1135.8 | W20: 1211.21 | X20: 1262.15 | Y20: 1313.14 | Z20: 1351.53 | AA20: 1374.24 | AB20: 1395.94 | AC20: 1418.29 | AD20: 1440.61 | AE20: 1465.75 | AF20: 1496.37 | AG20: 1553 | AH20: 1612.17 | AI20: 1671.52 | AJ20: 1735.27 | AK20: 1789.38 | AL20: 1845.49 | AM20: 1845.49 | AN20: 1845.49 | AO20: 1902.12 | AP20: 1950.82 | AQ20: 2003.56 | AR20: 2072.09 | AS20: 2138.88 | AT20: 2208.45
A21: 11 | B21: Касьяненко А.А. | C21: =INDEX($H21:$IV21,1,COUNTA($H21:$IV21)) -> 24123.17 | D21: =INDEX($H21:$IV21,1,COUNTA($H21:$IV21)-1) -> 23923.71 | E21: -53.74 | F21: 1310 | G21: 36 | H21: 14637.01 | I21: 14918.96 | J21: 15179.77 | K21: 15434.64 | L21: 15697.91 | M21: 15940.4 | N21: 16193.45 | O21: 16452.05 | P21: 16748.74 | Q21: 17059.55 | R21: 17314.97 | S21: 17314.97 | T21: 17314.97 | U21: 17593.74 | V21: 17872.32 | W21: 18184.85 | X21: 18480.17 | Y21: 18779.41 | Z21: 19041.14 | AA21: 19278.08 | AB21: 19546.11 | AC21: 19917.94 | AD21: 20236.46 | AE21: 20538.04 | AF21: 20795.6 | AG21: 21073.94 | AH21: 21369.53 | AI21: 21665.46 | AJ21: 21989.79 | AK21: 22278.94 | AL21: 22578.02 | AM21: 22578.02 | AN21: 22578.02 | AO21: 22844.74 | AP21: 23121.11 | AQ21: 23442.09 | AR21: 23733.36 | AS21: 23923.71 | AT21: 24123.17
A22: 11 | B22: Касьяненко А.А. | C22: =INDEX($H22:$IV22,1,COUNTA($H22:$IV22)) -> 8324.13 | D22: =INDEX($H22:$IV22,1,COUNTA($H22:$IV22)-1) -> 8257.05 | G22: 36 | H22: 5503.28 | I22: 5590.3 | J22: 5669.81 | K22: 5736.64 | L22: 5815.22 | M22: 5887.69 | N22: 5957.97 | O22: 6039.97 | P22: 6128.45 | Q22: 6210.48 | R22: 6279.95 | S22: 6279.95 | T22: 6279.95 | U22: 6354.42 | V22: 6436.03 | W22: 6521.22 | X22: 6603.65 | Y22: 6683.32 | Z22: 6760.09 | AA22: 6835.37 | AB22: 6929.59 | AC22: 7042.62 | AD22: 7142.11 | AE22: 7224.56 | AF22: 7289.25 | AG22: 7377.44 | AH22: 7476.05 | AI22: 7565.61 | AJ22: 7656.63 | AK22: 7733.72 | AL22: 7811.4 | AM22: 7811.4 | AN22: 7811.4 | AO22: 7883.58 | AP22: 7965.77 | AQ22: 8066.26 | AR22: 8187.87 | AS22: 8257.05 | AT22: 8324.13
A23: 12 | B23: Ким Т.В. | C23: =INDEX($H23:$IV23,1,COUNTA($H23:$IV23)) -> 15245.87 | D23: =INDEX($H23:$IV23,1,COUNTA($H23:$IV23)-1) -> 14438.65 | G23: 18 | H23: 23410.77 | I23: 24185.52 | J23: 25286.35 | K23: 26185.61 | L23: 27061.95 | M23: 27760.37 | N23: 28223.35 | O23: 28664.03 | P23: 29517.07 | Q23: 30227.96 | R23: 30817.4 | S23: 31535.19 | T23: 31535.19 | U23: 31201.33 | V23: 31919.12 | W23: 32727.57 | X23: 33516.07 | Y23: 34293.26 | Z23: 35072.91 | AA23: 35846/212 | AB23: 846.1 | AC23: 1745.39 | AD23: 2828.17 | AE23: 3851.17 | AF23: 4570.88 | AG23: 5358.71 | AH23: 6222.1 | AI23: 7098.75 | AJ23: 8036.85 | AK23: 8901.69 | AL23: 9803.86 | AM23: 9803.86 | AN23: 9803.86 | AO23: 10564.33 | AP23: 11360.53 | AQ23: 12411 | AR23: 13574.52 | AS23: 14438.65 | AT23: 15245.87
A24: 12 | B24: Ким Т.В. | C24: =INDEX($H24:$IV24,1,COUNTA($H24:$IV24)) -> 4359.82 | D24: =INDEX($H24:$IV24,1,COUNTA($H24:$IV24)-1) -> 4132.3 | G24: 18 | H24: 8826.8 | I24: 9184.42 | J24: 9665.7 | K24: 10046.41 | L24: 10393.76 | M24: 10670.27 | N24: 10855.07 | O24: 11064.03 | P24: 11405.17 | Q24: 11664.25 | R24: 11901.42 | S24: 12180.54 | T24: 12180.54 | U24: 12043.51 | V24: 12322.63 | W24: 12627.76 | X24: 12941.29 | Y24: 13220.95 | Z24: 13466.79 | AA24: 13711/71 | AB24: 283.81 | AC24: 540.75 | AD24: 911.38 | AE24: 1219.76 | AF24: 1438.1 | AG24: 1642.42 | AH24: 1854.95 | AI24: 2089.08 | AJ24: 2347.57 | AK24: 2577.27 | AL24: 2823.07 | AM24: 2823.07 | AN24: 2823.07 | AO24: 3032.31 | AP24: 3242.76 | AQ24: 3521 | AR24: 3885.21 | AS24: 4132.3 | AT24: 4359.82
A25: 13 | B25: Клокова Е.В. | C25: =INDEX($H25:$IV25,1,COUNTA($H25:$IV25)) -> 16096.2 | D25: =INDEX($H25:$IV25,1,COUNTA($H25:$IV25)-1) -> 15843.36 | E25: 2920.69 | F25: 3000 | G25: 2 | H25: 7518.51 | I25: 7746.42 | J25: 7958.3 | K25: 8143.95 | L25: 8329.56 | M25: 8499.97 | N25: 8674.74 | O25: 8993.51 | P25: 9265.17 | Q25: 9623.61 | R25: 9819 | S25: 9819 | T25: 9819 | U25: 10067.39 | V25: 10301.4 | W25: 10519.2 | X25: 10705.24 | Y25: 10887.32 | Z25: 11045.58 | AA25: 11181.27 | AB25: 11365.84 | AC25: 11797.71 | AD25: 12260.41 | AE25: 12571.62 | AF25: 12898.48 | AG25: 13152.04 | AH25: 13376.67 | AI25: 13555.4 | AJ25: 13753.39 | AK25: 13933.45 | AL25: 14123.75 | AM25: 14123.75 | AN25: 14123.75 | AO25: 14264.82 | AP25: 14443.11 | AQ25: 14942.46 | AR25: 15433.86 | AS25: 15843.36 | AT25: 16096.2
A26: 13 | B26: Клокова Е.В. | C26: =INDEX($H26:$IV26,1,COUNTA($H26:$IV26)) -> 6602.25 | D26: =INDEX($H26:$IV26,1,COUNTA($H26:$IV26)-1) -> 6481.59 | G26: 2 | H26: 2990.3 | I26: 3080.48 | J26: 3182.35 | K26: 3266.39 | L26: 3350.21 | M26: 3423.55 | N26: 3497.25 | O26: 3659.24 | P26: 3733.36 | Q26: 3883.01 | R26: 3970.05 | S26: 3970.05 | T26: 3970.05 | U26: 4066.37 | V26: 4154.8 | W26: 4236.81 | X26: 4316.73 | Y26: 4397.84 | Z26: 4466.4 | AA26: 4521.7 | AB26: 4590.32 | AC26: 4756.46 | AD26: 4956.7 | AE26: 5092.37 | AF26: 5239.45 | AG26: 5340.9 | AH26: 5419.58 | AI26: 5495.86 | AJ26: 5577.57 | AK26: 5647.99 | AL26: 5721.37 | AM26: 5721.37 | AN26: 5721.37 | AO26: 5778.89 | AP26: 5848.13 | AQ26: 6086.81 | AR26: 6287.74 | AS26: 6481.59 | AT26: 6602.25
A27: 14 | B27: Коваленко Р.Т. | C27: =INDEX($H27:$IV27,1,COUNTA($H27:$IV27)) -> 10.31 | D27: =INDEX($H27:$IV27,1,COUNTA($H27:$IV27)-1) -> 8.35 | E27: -63.18 | F27: 100 | G27: 9 | H27: 2.37 | I27: 2.37 | J27: 2.37 | K27: 2.67 | L27: 2.67 | M27: 2.69 | N27: 2.69 | O27: 3.18 | P27: 3.22 | Q27: 3.22 | R27: 3.22 | S27: 3.22 | T27: 3.22 | U27: 3.22 | V27: 3.22 | W27: 3.22 | X27: 3.22 | Y27: 3.64 | Z27: 3.75 | AA27: 3.92 | AB27: 3.94 | AC27: 3.94 | AD27: 3.95 | AE27: 4.14 | AF27: 4.14 | AG27: 4.14 | AH27: 4.15 | AI27: 4.15 | AJ27: 4.15 | AK27: 4.15 | AL27: 6.3 | AM27: 6.3 | AN27: 6.3 | AO27: 6.3 | AP27: 6.83 | AQ27: 6.83 | AR27: 7.82 | AS27: 8.35 | AT27: 10.31
A28: 14 | B28: Коваленко Р.Т. | C28: =INDEX($H28:$IV28,1,COUNTA($H28:$IV28)) -> 0 | D28: =INDEX($H28:$IV28,1,COUNTA($H28:$IV28)-1) -> 0 | G28: 9 | H28: 0 | I28: 0 | J28: 0 | K28: 0 | L28: 0 | M28: 0 | N28: 0 | O28: 0 | P28: 0 | Q28: 0 | R28: 0 | S28: 0 | T28: 0 | U28: 0 | V28: 0 | W28: 0 | X28: 0 | Y28: 0 | Z28: 0 | AA28: 0 | AB28: 0 | AC28: 0 | AD28: 0 | AE28: 0 | AF28: 0 | AG28: 0 | AH28: 0 | AI28: 0 | AJ28: 0 | AK28: 0 | AL28: 0 | AM28: 0 | AN28: 0 | AO28: 0 | AP28: 0 | AQ28: 0 | AR28: 0 | AS28: 0 | AT28: 0
A29: 15 | B29: Кралькина И.А. | C29: =INDEX($H29:$IV29,1,COUNTA($H29:$IV29)) -> 140791.9 | D29: =INDEX($H29:$IV29,1,COUNTA($H29:$IV29)-1) -> 139337.75 | E29: 16847.63 | F29: 16850 | G29: 15 | H29: 82816.23 | I29: 84568.17 | J29: 86304.51 | K29: 87699.32 | L29: 89110.3 | M29: 90555.48 | N29: 92016.79 | O29: 93818.41 | P29: 96103.76 | Q29: 97994.44 | R29: 99336.12 | S29: 99336.12 | T29: 99336.12 | U29: 100656.74 | V29: 102349.24 | W29: 104511.41 | X29: 106170.25 | Y29: 107769.92 | Z29: 109111.59 | AA29: 110192.63 | AB29: 111891.27 | AC29: 114236.35 | AD29: 116416.57 | AE29: 118392.45 | AF29: 119656.96 | AG29: 121298.68 | AH29: 123378.9 | AI29: 125105.81 | AJ29: 127270.5 | AK29: 128825.53 | AL29: 130282.72 | AM29: 130282.72 | AN29: 130282.72 | AO29: 131510.26 | AP29: 133034.35 | AQ29: 135250.69 | AR29: 137780.45 | AS29: 139337.75 | AT29: 140791.9
A30: 15 | B30: Кралькина И.А. | C30: =INDEX($H30:$IV30,1,COUNTA($H30:$IV30)) -> 52726.58 | D30: =INDEX($H30:$IV30,1,COUNTA($H30:$IV30)-1) -> 52145 | G30: 15 | H30: 30420.26 | I30: 30994.06 | J30: 31520.93 | K30: 31938.85 | L30: 32404.44 | M30: 32843.62 | N30: 33296.42 | O30: 33956.09 | P30: 34731.81 | Q30: 35422.37 | R30: 35945.13 | S30: 35945.13 | T30: 35945.13 | U30: 36445.29 | V30: 37110.37 | W30: 37986.51 | X30: 38710.66 | Y30: 39366.84 | Z30: 39895.4 | AA30: 40294.48 | AB30: 40994.2 | AC30: 41937.39 | AD30: 42836.7 | AE30: 43587.29 | AF30: 44121.01 | AG30: 44786.76 | AH30: 45710.31 | AI30: 46463.51 | AJ30: 47394.84 | AK30: 48055.85 | AL30: 48653.14 | AM30: 48653.14 | AN30: 48653.14 | AO30: 49142.26 | AP30: 49696.26 | AQ30: 50517.51 | AR30: 51488.36 | AS30: 52145 | AT30: 52726.58
A31: 16 | B31: Кудряшов Ю.Ю. | C31: =INDEX($H31:$IV31,1,COUNTA($H31:$IV31)) -> 11353.14 | D31: =INDEX($H31:$IV31,1,COUNTA($H31:$IV31)-1) -> 11109.4 | E31: 4352.1 | F31: 916.75 | G31: 41 | H31: 3887.35 | I31: 4156.67 | J31: 4407.49 | K31: 4617.1 | L31: 4838.46 | M31: 5027.45 | N31: 5177.1 | O31: 5331.51 | P31: 5596.89 | Q31: 5799.76 | R31: 6014.14 | S31: 6014.14 | T31: 6014.14 | U31: 6260.01 | V31: 6542 | W31: 6802.19 | X31: 7040.35 | Y31: 7270.76 | Z31: 7500.86 | AA31: 7705.86 | AB31: 7847.58 | AC31: 8068.56 | AD31: 8280.95 | AE31: 8489.9 | AF31: 8690.82 | AG31: 8937.6 | AH31: 9206.25 | AI31: 9457.34 | AJ31: 9720.32 | AK31: 9947.34 | AL31: 10194.37 | AM31: 10194.37 | AN31: 10194.37 | AO31: 10405.08 | AP31: 10586.01 | AQ31: 10762.85 | AR31: 10940.08 | AS31: 11109.4 | AT31: 11353.14
A32: 16 | B32: Кудряшов Ю.Ю. | C32: =INDEX($H32:$IV32,1,COUNTA($H32:$IV32)) -> 3589.45 | D32: =INDEX($H32:$IV32,1,COUNTA($H32:$IV32)-1) -> 3513.27 | G32: 41 | H32: 1265.47 | I32: 1351.15 | J32: 1436.65 | K32: 1509.45 | L32: 1578.73 | M32: 1636.96 | N32: 1683.54 | O32: 1733.58 | P32: 1814.44 | Q32: 1875.83 | R32: 1942.69 | S32: 1942.69 | T32: 1942.69 | U32: 2021.22 | V32: 2117.26 | W32: 2202.29 | X32: 2276.48 | Y32: 2350.7 | Z32: 2412.97 | AA32: 2468.11 | AB32: 2510.82 | AC32: 2577.13 | AD32: 2633.64 | AE32: 2683.45 | AF32: 2738.41 | AG32: 2815.58 | AH32: 2903.5 | AI32: 2989.64 | AJ32: 3080.49 | AK32: 3160.95 | AL32: 3245.68 | AM32: 3245.68 | AN32: 3245.68 | AO32: 3315.67 | AP32: 3368.21 | AQ32: 3419.91 | AR32: 3467.33 | AS32: 3513.27 | AT32: 3589.45
A33: 17 | B33: Курашин А.П. | C33: =INDEX($H33:$IV33,1,COUNTA($H33:$IV33)) -> 72.2 | D33: =INDEX($H33:$IV33,1,COUNTA($H33:$IV33)-1) -> 67.7 | E33: -268.98 | G33: 42 | H33: 0.8 | I33: 0.8 | J33: 0.8 | K33: 0.8 | L33: 0.8 | M33: 0.8 | N33: 1.7 | O33: 1.7 | P33: 1.7 | Q33: 1.7 | R33: 1.7 | S33: 1.7 | T33: 1.7 | U33: 1.7 | V33: 1.7 | W33: 1.7 | X33: 4.8 | Y33: 16.1 | Z33: 17.8 | AA33: 23.9 | AB33: 29.3 | AC33: 39.6 | AD33: 52.8 | AE33: 57.4 | AF33: 60.4 | AG33: 60.4 | AH33: 60.4 | AI33: 60.4 | AJ33: 60.4 | AK33: 60.4 | AL33: 60.4 | AM33: 60.4 | AN33: 60.4 | AO33: 60.4 | AP33: 60.4 | AQ33: 60.4 | AR33: 62.4 | AS33: 67.7 | AT33: 72.2
A34: 18 | B34: Лисина H.А. | C34: =INDEX($H34:$IV34,1,COUNTA($H34:$IV34)) -> 10522.53 | D34: =INDEX($H34:$IV34,1,COUNTA($H34:$IV34)-1) -> 10383.83 | E34: 2158.24 | F34: =919.03+1239.21 -> 2158.24 | G34: 7 | H34: 4022.14 | I34: 4313.31 | J34: 4588.48 | K34: 4798.65 | L34: 5000.23 | M34: 5235.13 | N34: 5426.22 | O34: 5606.62 | P34: 5784.11 | Q34: 5964.67 | R34: 6133.82 | S34: 6133.82 | T34: 6133.82 | U34: 6322.82 | V34: 6551.89 | W34: 6784.24 | X34: 6987.75 | Y34: 7168.74 | Z34: 7386.72 | AA34: 7576.28 | AB34: 7775.64 | AC34: 8002.5 | AD34: 8157.17 | AE34: 8256.24 | AF34: 8343.28 | AG34: 8461.58 | AH34: 8661.16 | AI34: 8886.96 | AJ34: 9101.15 | AK34: 9322.66 | AL34: 9509.37 | AM34: 9509.37 | AN34: 9509.37 | AO34: 9696.49 | AP34: 9859.64 | AQ34: 10031.8 | AR34: 10234.08 | AS34: 10383.83 | AT34: 10522.53
A35: 18 | B35: Лисина H.А. | C35: =INDEX($H35:$IV35,1,COUNTA($H35:$IV35)) -> 2902.79 | D35: =INDEX($H35:$IV35,1,COUNTA($H35:$IV35)-1) -> 2867.84 | G35: 7 | H35: 973.15 | I35: 1046.73 | J35: 1133.17 | K35: 1206.01 | L35: 1256.01 | M35: 1321.41 | N35: 1376.84 | O35: 1429.16 | P35: 1478.18 | Q35: 1522.2 | R35: 1573.29 | S35: 1573.29 | T35: 1573.29 | U35: 1629.92 | V35: 1711.06 | W35: 1785.53 | X35: 1870.02 | Y35: 1943.52 | Z35: 2005.24 | AA35: 2062.2 | AB35: 2112.19 | AC35: 2158.63 | AD35: 2209.46 | AE35: 2248.38 | AF35: 2283.01 | AG35: 2323.94 | AH35: 2378 | AI35: 2448.11 | AJ35: 2510.54 | AK35: 2573.79 | AL35: 2637.42 | AM35: 2637.42 | AN35: 2637.42 | AO35: 2690.99 | AP35: 2736.63 | AQ35: 2778.74 | AR35: 2827.09 | AS35: 2867.84 | AT35: 2902.79
A36: 19 | B36: Лисина Н.А. | C36: =INDEX($H36:$IV36,1,COUNTA($H36:$IV36)) -> 116.75 | D36: =INDEX($H36:$IV36,1,COUNTA($H36:$IV36)-1) -> 99.54 | E36: 415.72 | F36: =176.69+239.03 -> 415.72 | G36: 38 | H36: 154.8 | I36: 154.8 | J36: 154.8 | K36: 154.8 | L36: 0 | M36: 0.16 | N36: 0.16 | O36: 0.16 | P36: 0.16 | Q36: 0.16 | R36: 0.16 | S36: 0.16 | T36: 0.16 | U36: 0.16 | V36: 0.16 | W36: 0.16 | X36: 0.31 | Y36: 0.84 | Z36: 1 | AA36: 1.17 | AB36: 1.21 | AC36: 1.9 | AD36: 2.48 | AE36: 2.48 | AF36: 2.69 | AG36: 2.73 | AH36: 2.78 | AI36: 2.83 | AJ36: 2.83 | AK36: 2.86 | AL36: 2.86 | AM36: 2.86 | AN36: 2.86 | AO36: 2.86 | AP36: 6.42 | AQ36: 34.77 | AR36: 72.63 | AS36: 99.54 | AT36: 116.75
A37: 19 | B37: Лисина Н.А. | C37: =INDEX($H37:$IV37,1,COUNTA($H37:$IV37)) -> 43.72 | D37: =INDEX($H37:$IV37,1,COUNTA($H37:$IV37)-1) -> 35.53 | G37: 38 | H37: 0 | I37: 0 | J37: 0 | K37: 0 | L37: 0 | M37: 0 | N37: 0 | O37: 0 | P37: 0 | Q37: 0 | R37: 0 | S37: 0 | T37: 0 | U37: 0 | V37: 0 | W37: 0 | X37: 0.02 | Y37: 0.02 | Z37: 0.02 | AA37: 0.02 | AB37: 0.05 | AC37: 0.12 | AD37: 0.21 | AE37: 0.21 | AF37: 0.28 | AG37: 0.28 | AH37: 0.28 | AI37: 0.28 | AJ37: 0.28 | AK37: 0.29 | AL37: 0.29 | AM37: 0.29 | AN37: 0.29 | AO37: 0.29 | AP37: 0.29 | AQ37: 10.35 | AR37: 23.94 | AS37: 35.53 | AT37: 43.72
A38: 20 | B38: Макарова О.Н. | C38: =INDEX($H38:$IV38,1,COUNTA($H38:$IV38)) -> 25224.3 | D38: =INDEX($H38:$IV38,1,COUNTA($H38:$IV38)-1) -> 24772.9 | E38: -568.91 | F38: 1000 | G38: 6 | H38: 8615.7 | I38: 8901.2 | J38: 10077.9 | K38: 10733.9 | L38: 11300.6 | M38: 11552.6 | N38: 11667.4 | O38: 11783.8 | P38: 11882.3 | Q38: 11992.6 | R38: 12086.6 | S38: 12086.6 | T38: 12086.6 | U38: 12448.4 | V38: 13196.9 | W38: 14061 | X38: 14954.3 | Y38: 15602.1 | Z38: 15893.5 | AA38: 16018.7 | AB38: 16162.6 | AC38: 16319.3 | AD38: 16378.1 | AE38: 16638 | AF38: 16938 | AG38: 17630.4 | AH38: 18707.3 | AI38: 20000.7 | AJ38: 21585.1 | AK38: 22497.9 | AL38: 23569.2 | AM38: 23569.2 | AN38: 23569.2 | AO38: 23965.3 | AP38: 24128.8 | AQ38: 24317.3 | AR38: 24531.7 | AS38: 24772.9 | AT38: 25224.3
A39: 21 | B39: Милакина М.В. | C39: =INDEX($H39:$IV39,1,COUNTA($H39:$IV39)) -> 26511.9 | D39: =INDEX($H39:$IV39,1,COUNTA($H39:$IV39)-1) -> 26168.58 | E39: 2064.55 | F39: 4600 | G39: 31 | H39: 14487.48 | I39: 14845.08 | J39: 15372.63 | K39: 15643.41 | L39: 15898.35 | M39: 16269.91 | N39: 16606.34 | O39: 17021.92 | P39: 17456.57 | Q39: 17905.24 | R39: 18265.72 | S39: 18265.72 | T39: 18265.72 | U39: 18599.53 | V39: 18977.53 | W39: 19571.38 | X39: 20115.09 | Y39: 20416.53 | Z39: 20711.42 | AA39: 21000.85 | AB39: 21202.93 | AC39: 21434.05 | AD39: 21650.96 | AE39: 21909.35 | AF39: 22128.72 | AG39: 22320.82 | AH39: 22670.19 | AI39: 23251.79 | AJ39: 23927.94 | AK39: 24339.54 | AL39: 24718.26 | AM39: 24718.26 | AN39: 24718.26 | AO39: 25011.78 | AP39: 25271.84 | AQ39: 25579.34 | AR39: 25855.06 | AS39: 26168.58 | AT39: 26511.9
A40: 21 | B40: Милакина М.В. | C40: =INDEX($H40:$IV40,1,COUNTA($H40:$IV40)) -> 14148.45 | D40: =INDEX($H40:$IV40,1,COUNTA($H40:$IV40)-1) -> 13997.3 | G40: 31 | H40: 8380.91 | I40: 8618.74 | J40: 8944.27 | K40: 9113.17 | L40: 9238.01 | M40: 9423.11 | N40: 9598.55 | O40: 9777.78 | P40: 9935.14 | Q40: 10153.39 | R40: 10333.16 | S40: 10333.16 | T40: 10333.16 | U40: 10506.4 | V40: 10712.1 | W40: 11015.98 | X40: 11296.96 | Y40: 11434.8 | Z40: 11567.89 | AA40: 11682.14 | AB40: 11792.6 | AC40: 11897.12 | AD40: 12007.29 | AE40: 12122.42 | AF40: 12221.36 | AG40: 12304.76 | AH40: 12465.13 | AI40: 12749.17 | AJ40: 13076.91 | AK40: 13283.06 | AL40: 13461.28 | AM40: 13461.28 | AN40: 13461.28 | AO40: 13596.65 | AP40: 13702.02 | AQ40: 13799.4 | AR40: 13888.46 | AS40: 13997.3 | AT40: 14148.45
...

Sheet Calc
T1: =Arhive!B1 -> 2025-10-01
B2: =Arhive!B94 -> Организация: Товарищество собственников недвижимости "жилищно-строительное товарищество индивидуальных застройщиков "Столетовский"
B3: =Arhive!B95 -> ИНН: 9201505978; КПП: 920101001; ФИЛИАЛ "ЦЕНТРАЛЬНЫЙ" БАНКА ВТБ (ПАО) в г. Москве;
B4: =Arhive!B96 -> БИК 044525411; Р/с 40703810824317000026; К/с 30101810145250000411
B5: =Arhive!B97 -> тел. +7(978) 812-13-99, e-mail: tsn-gstiz-stoletovskiy@yandex.ru
B7: г. Севастополь, ТСН "ЖСТИЗ "СТОЛЕТОВСКИЙ" | F7: Показания по прибору учета электроэнергии | J7: Расчет обьема, кВт.*ч | M7: Ставка тарифа, р./кВт.*ч | P7: Начислено, руб. | S7: Сумма, руб. | T7: Долг / Переплата "-", руб. | U7: Учтена оплата, руб. | V7: К оплате, руб.
B8: П/п | C8: Уч.№ | D8: Потребитель | E8: Тарифная зона | F8: Текущий месяц, кВт.*ч | G8: Предыдущий месяц, кВт.*ч | H8: Расход, кВт*ч | I8: Соотно- шение, % | J8: Блок 1 | K8: Блок 2 | L8: Блок 3 | M8: Блок 1 | N8: Блок 2 | O8: Блок 3 | P8: Блок 1 | Q8: Блок 2 | R8: Блок 3
B9: 1 | C9: 2 | D9: 3 | E9: 4 | F9: 5 | G9: 6 | H9: 7 | I9: 8 | J9: 9 | K9: 10 | L9: 11 | M9: 12 | N9: 13 | O9: 14 | P9: 15 | Q9: 16 | R9: 17 | S9: 18 | T9: 19 | U9: 20 | V9: 21
B10: =Arhive!A2 -> 1 | C10: =Arhive!G2 -> 21 | D10: Гаценко Н.Г. | E10: День (Т1) | F10: =Arhive!C2 -> 683.9 | G10: =Arhive!D2 -> 678.15 | H10: =F10-G10 -> 5.75 | I10: =IF(H10=0,0,H10*100/(H10+H11)) -> 92.891761 | J10: =IF((H10+H11)>150,IF(H10=0,0,H10*100/(H10+H11)*150/100),H10) -> 5.75 | K10: =IF(H10+H11<600,H10-J10,450*(IF(H10=0,0,H10*100/(H10+H11)))/100) -> 0 | L10: =H10-J10-K10 -> 0 | M10: 5.05 | N10: 5.47 | O10: 9.4 | P10: =IF(H10<J10,H10*M10,J10*M10) -> 29.0375 | Q10: =IF(K10<0,0,K10*N10) -> 0 | R10: =IF(L10<0,0,L10*O10) -> 0 | S10: =ROUND(SUM(P10:R11),2) -> 30.59 | T10: =Arhive!E2 -> -282.57 | U10: =Arhive!F2 -> 500 | V10: =SUM(S10:T11)-U10 -> -751.98
B11: 1 | D11: =D10 -> Гаценко Н.Г. | E11: Ночь (Т2) | F11: =Arhive!C3 -> 105.13 | G11: =Arhive!D3 -> 104.69 | H11: =F11-G11 -> 0.44 | I11: =IF(H11=0,0,H11*100/(H11+H10)) -> 7.1082391 | J11: =IF((H10+H11)>150,IF(H10=0,0,H11*100/(H10+H11)*150/100),H11) -> 0.44 | K11: =IF(H11+H10<600,H11-J11,450*(IF(H11=0,0,H11*100/(H11+H10)))/100) -> 0 | L11: =H11-K11-J11 -> 0 | M11: 3.52 | N11: 4.21 | O11: 6.99 | P11: =IF(H11<J11,H11*M11,J11*M11) -> 1.5488 | Q11: =IF(K11<0,0,K11*N11) -> 0 | R11: =IF(L11<0,0,L11*O11) -> 0
B12: =Arhive!A4 -> 2 | C12: =Arhive!G4 -> 54 | D12: Дикарев А.А. | E12: День (Т1) | F12: =Arhive!C4 -> 0 | G12: =Arhive!D4 -> 0 | H12: =F12-G12 -> 0 | I12: =IF(H12=0,0,H12*100/(H12+H13)) -> 0 | J12: =IF((H12+H13)>150,IF(H12=0,0,H12*100/(H12+H13)*150/100),H12) -> 0 | K12: =IF(H12+H13<600,H12-J12,450*(IF(H12=0,0,H12*100/(H12+H13)))/100) -> 0 | L12: =H12-J12-K12 -> 0 | M12: 5.05 | N12: 5.47 | O12: 9.4 | P12: =IF(H12<J12,H12*M12,J12*M12) -> 0 | Q12: =IF(K12<0,0,K12*N12) -> 0 | R12: =IF(L12<0,0,L12*O12) -> 0 | S12: =ROUND(SUM(P12:R13),2) -> 0 | T12: =Arhive!E4 -> 0 | U12: =Arhive!F8 -> 0 | V12: =SUM(S12:T13)-U12 -> 0
B13: 2 | D13: =D12 -> Дикарев А.А. | E13: Ночь (Т2) | F13: =Arhive!C5 -> 0 | G13: =Arhive!D5 -> 0 | H13: =F13-G13 -> 0 | I13: =IF(H13=0,0,H13*100/(H13+H12)) -> 0 | J13: =IF((H12+H13)>150,IF(H12=0,0,H13*100/(H12+H13)*150/100),H13) -> 0 | K13: =IF(H13+H12<600,H13-J13,450*(IF(H13=0,0,H13*100/(H13+H12)))/100) -> 0 | L13: =H13-K13-J13 -> 0 | M13: 3.52 | N13: 4.21 | O13: 6.99 | P13: =IF(H13<J13,H13*M13,J13*M13) -> 0 | Q13: =IF(K13<0,0,K13*N13) -> 0 | R13: =IF(L13<0,0,L13*O13) -> 0
B14: =Arhive!A6 -> 3 | C14: =Arhive!G6 -> 51 | D14: Дмитриев А.В. | E14: День (Т1) | F14: =Arhive!C6 -> 23549.72 | G14: =Arhive!D6 -> 23280.28 | H14: =F14-G14 -> 269.44 | I14: =IF(H14=0,0,H14*100/(H14+H15)) -> 58.930056 | J14: =IF((H14+H15)>150,IF(H14=0,0,H14*100/(H14+H15)*150/100),H14) -> 88.395083 | K14: =IF(H14+H15<600,H14-J14,450*(IF(H14=0,0,H14*100/(H14+H15)))/100) -> 181.04492 | L14: =H14-J14-K14 -> 0 | M14: 5.05 | N14: 5.47 | O14: 9.4 | P14: =IF(H14<J14,H14*M14,J14*M14) -> 446.39517 | Q14: =IF(K14<0,0,K14*N14) -> 990.31569 | R14: =IF(L14<0,0,L14*O14) -> 0 | S14: =ROUND(SUM(P14:R15),2) -> 2184.76 | T14: =Arhive!E6 -> 8160.23 | U14: =Arhive!F6 -> 0 | V14: =SUM(S14:T15)-U14 -> 10344.99
B15: 3 | D15: =D14 -> Дмитриев А.В. | E15: Ночь (Т2) | F15: =Arhive!C7 -> 8771.92 | G15: =Arhive!D7 -> 8584.14 | H15: =F15-G15 -> 187.78 | I15: =IF(H15=0,0,H15*100/(H15+H14)) -> 41.069944 | J15: =IF((H14+H15)>150,IF(H14=0,0,H15*100/(H14+H15)*150/100),H15) -> 61.604917 | K15: =IF(H15+H14<600,H15-J15,450*(IF(H15=0,0,H15*100/(H15+H14)))/100) -> 126.17508 | L15: =H15-K15-J15 -> 0 | M15: 3.52 | N15: 4.21 | O15: 6.99 | P15: =IF(H15<J15,H15*M15,J15*M15) -> 216.84931 | Q15: =IF(K15<0,0,K15*N15) -> 531.1971 | R15: =IF(L15<0,0,L15*O15) -> 0
B16: =Arhive!A8 -> 4 | C16: =Arhive!G8 -> 35 | D16: Егоров Е.Ю. | E16: День (Т1) | F16: =Arhive!C8 -> 20395.7 | G16: =Arhive!D8 -> 20213.43 | H16: =F16-G16 -> 182.27 | I16: =IF(H16=0,0,H16*100/(H16+H17)) -> 72.597284 | J16: =IF((H16+H17)>150,IF(H16=0,0,H16*100/(H16+H17)*150/100),H16) -> 108.89593 | K16: =IF(H16+H17<600,H16-J16,450*(IF(H16=0,0,H16*100/(H16+H17)))/100) -> 73.374075 | L16: =H16-J16-K16 -> 0 | M16: 5.05 | N16: 5.47 | O16: 9.4 | P16: =IF(H16<J16,H16*M16,J16*M16) -> 549.92442 | Q16: =IF(K16<0,0,K16*N16) -> 401.35619 | R16: =IF(L16<0,0,L16*O16) -> 0 | S16: =ROUND(SUM(P16:R17),2) -> 1212.57 | T16: =Arhive!E8 -> 2391.64 | U16: =Arhive!F8 -> 0 | V16: =SUM(S16:T17)-U16 -> 3604.21
B17: 3 | D17: =D16 -> Егоров Е.Ю. | E17: Ночь (Т2) | F17: =Arhive!C9 -> 5911.38 | G17: =Arhive!D9 -> 5842.58 | H17: =F17-G17 -> 68.8 | I17: =IF(H17=0,0,H17*100/(H17+H16)) -> 27.402716 | J17: =IF((H16+H17)>150,IF(H16=0,0,H17*100/(H16+H17)*150/100),H17) -> 41.104075 | K17: =IF(H17+H16<600,H17-J17,450*(IF(H17=0,0,H17*100/(H17+H16)))/100) -> 27.695925 | L17: =H17-K17-J17 -> 0 | M17: 3.52 | N17: 4.21 | O17: 6.99 | P17: =IF(H17<J17,H17*M17,J17*M17) -> 144.68634 | Q17: =IF(K17<0,0,K17*N17) -> 116.59985 | R17: =IF(L17<0,0,L17*O17) -> 0
B18: =Arhive!A10 -> 5 | C18: =Arhive!G10 -> 46 | D18: Ефимов В.В. | E18: День (Т1) | F18: =Arhive!C10 -> 2980.63 | G18: =Arhive!D10 -> 2953.62 | H18: =F18-G18 -> 27.01 | I18: =IF(H18=0,0,H18*100/(H18+H19)) -> 84.40625 | J18: =IF((H18+H19)>150,IF(H18=0,0,H18*100/(H18+H19)*150/100),H18) -> 27.01 | K18: =IF(H18+H19<600,H18-J18,450*(IF(H18=0,0,H18*100/(H18+H19)))/100) -> 0 | L18: =H18-J18-K18 -> 0 | M18: 5.05 | N18: 5.47 | O18: 9.4 | P18: =IF(H18<J18,H18*M18,J18*M18) -> 136.4005 | Q18: =IF(K18<0,0,K18*N18) -> 0 | R18: =IF(L18<0,0,L18*O18) -> 0 | S18: =ROUND(SUM(P18:R19),2) -> 153.97 | T18: =Arhive!E10 -> -299.95 | U18: =Arhive!F10 -> 0 | V18: =SUM(S18:T19)-U18 -> -145.98
B19: 3 | D19: =D18 -> Ефимов В.В. | E19: Ночь (Т2) | F19: =Arhive!C11 -> 561.35 | G19: =Arhive!D11 -> 556.36 | H19: =F19-G19 -> 4.99 | I19: =IF(H19=0,0,H19*100/(H19+H18)) -> 15.59375 | J19: =IF((H18+H19)>150,IF(H18=0,0,H19*100/(H18+H19)*150/100),H19) -> 4.99 | K19: =IF(H19+H18<600,H19-J19,450*(IF(H19=0,0,H19*100/(H19+H18)))/100) -> 0 | L19: =H19-K19-J19 -> 0 | M19: 3.52 | N19: 4.21 | O19: 6.99 | P19: =IF(H19<J19,H19*M19,J19*M19) -> 17.5648 | Q19: =IF(K19<0,0,K19*N19) -> 0 | R19: =IF(L19<0,0,L19*O19) -> 0
B20: =Arhive!A12 -> 6 | C20: =Arhive!G12 -> 17 | D20: Заруба Л.С. | E20: Тариф 1 | F20: =Arhive!C12 -> 10011.4 | G20: =Arhive!D12 -> 9822.8 | H20: =F20-G20 -> 188.6 | I20: =IF(H20=0,0,H20*100/H20) -> 100 | J20: =IF(H20>150,IF(H20=0,0,H20*100/H20*150/100),H20) -> 150 | K20: =IF(H20<600,H20-J20,450*(IF(H20=0,0,H20*100/H20))/100) -> 38.6 | L20: =H20-J20-K20 -> 0 | M20: 5.05 | N20: 5.47 | O20: 9.4 | P20: =IF(H20<J20,H20*M20,J20*M20) -> 757.5 | Q20: =IF(K20<0,0,K20*N20) -> 211.142 | R20: =IF(L20<0,0,L20*O20) -> 0 | S20: =ROUND(SUM(P20:R20),2) -> 968.64 | T20: =Arhive!E12 -> -1452.49 | U20: =Arhive!F12 -> 0 | V20: =SUM(S20:T20)-U20 -> -483.85
B21: =Arhive!A13 -> 7 | C21: =Arhive!G13 -> 3 | D21: Зырянов Д.Н. | E21: День (Т1) | F21: =Arhive!C13 -> 20682.76 | G21: =Arhive!D13 -> 20464.02 | H21: =F21-G21 -> 218.74 | I21: =IF(H21=0,0,H21*100/(H21+H22)) -> 75.19681 | J21: =IF((H21+H22)>150,IF(H21=0,0,H21*100/(H21+H22)*150/100),H21) -> 112.79521 | K21: =IF(H21+H22<600,H21-J21,450*(IF(H21=0,0,H21*100/(H21+H22)))/100) -> 105.94479 | L21: =H21-J21-K21 -> 0 | M21: 5.05 | N21: 5.47 | O21: 9.4 | P21: =IF(H21<J21,H21*M21,J21*M21) -> 569.61583 | Q21: =IF(K21<0,0,K21*N21) -> 579.51798 | R21: =IF(L21<0,0,L21*O21) -> 0 | S21: =ROUND(SUM(P21:R22),2) -> 1427.21 | T21: =Arhive!E13 -> 1079.56 | U21: =Arhive!F13 -> 1081.4 | V21: =SUM(S21:T22)-U21 -> 1425.37
B22: 7 | D22: =D21 -> Зырянов Д.Н. | E22: Ночь (Т2) | F22: =Arhive!C14 -> 6661.37 | G22: =Arhive!D14 -> 6589.22 | H22: =F22-G22 -> 72.15 | I22: =IF(H22=0,0,H22*100/(H22+H21)) -> 24.80319 | J22: =IF((H21+H22)>150,IF(H21=0,0,H22*100/(H21+H22)*150/100),H22) -> 37.204785 | K22: =IF(H22+H21<600,H22-J22,450*(IF(H22=0,0,H22*100/(H22+H21)))/100) -> 34.945215 | L22: =H22-K22-J22 -> 0 | M22: 3.52 | N22: 4.21 | O22: 6.99 | P22: =IF(H22<J22,H22*M22,J22*M22) -> 130.96084 | Q22: =IF(K22<0,0,K22*N22) -> 147.11935 | R22: =IF(L22<0,0,L22*O22) -> 0
B23: =Arhive!A15 -> 8 | C23: =Arhive!G15 -> 44 | D23: =Arhive!B15 -> Кавун А.И. | E23: День (Т1) | F23: =Arhive!C15 -> 12116.96 | G23: =Arhive!D15 -> 11948.97 | H23: =F23-G23 -> 167.99 | I23: =IF(H23=0,0,H23*100/(H23+H24)) -> 76.21705 | J23: =IF((H23+H24)>150,IF(H23=0,0,H23*100/(H23+H24)*150/100),H23) -> 114.32558 | K23: =IF(H23+H24<600,H23-J23,450*(IF(H23=0,0,H23*100/(H23+H24)))/100) -> 53.664425 | L23: =H23-J23-K23 -> 0 | M23: 5.05 | N23: 5.47 | O23: 9.4 | P23: =IF(H23<J23,H23*M23,J23*M23) -> 577.34415 | Q23: =IF(K23<0,0,K23*N23) -> 293.5444 | R23: =IF(L23<0,0,L23*O23) -> 0 | S23: =ROUND(SUM(P23:R24),2) -> 1066.96 | T23: =Arhive!E15 -> 1643.12 | U23: =Arhive!F15 -> 6643 | V23: =SUM(S23:T24)-U23 -> -3932.92
B24: 8 | D24: =D23 -> Кавун А.И. | E24: Ночь (Т2) | F24: =Arhive!C16 -> 5784.35 | G24: =Arhive!D16 -> 5731.93 | H24: =F24-G24 -> 52.42 | I24: =IF(H24=0,0,H24*100/(H24+H23)) -> 23.78295 | J24: =IF((H23+H24)>150,IF(H23=0,0,H24*100/(H23+H24)*150/100),H24) -> 35.674425 | K24: =IF(H24+H23<600,H24-J24,450*(IF(H24=0,0,H24*100/(H24+H23)))/100) -> 16.745575 | L24: =H24-K24-J24 -> 0 | M24: 3.52 | N24: 4.21 | O24: 6.99 | P24: =IF(H24<J24,H24*M24,J24*M24) -> 125.57398 | Q24: =IF(K24<0,0,K24*N24) -> 70.498871 | R24: =IF(L24<0,0,L24*O24) -> 0
B25: =Arhive!A17 -> 9 | C25: =Arhive!G17 -> 22 | D25: =Arhive!B17 -> Калашников В.В. | E25: День (Т1) | F25: =Arhive!C17 -> 2152.36 | G25: =Arhive!D17 -> 2130 | H25: =F25-G25 -> 22.36 | I25: =IF(H25=0,0,H25*100/(H25+H26)) -> 64.032073 | J25: =IF((H25+H26)>150,IF(H25=0,0,H25*100/(H25+H26)*150/100),H25) -> 22.36 | K25: =IF(H25+H26<600,H25-J25,450*(IF(H25=0,0,H25*100/(H25+H26)))/100) -> 0 | L25: =H25-J25-K25 -> 0 | M25: 5.05 | N25: 5.47 | O25: 9.4 | P25: =IF(H25<J25,H25*M25,J25*M25) -> 112.918 | Q25: =IF(K25<0,0,K25*N25) -> 0 | R25: =IF(L25<0,0,L25*O25) -> 0 | S25: =ROUND(SUM(P25:R26),2) -> 157.13 | T25: =Arhive!E17 -> 529.91 | U25: =Arhive!F17 -> 0 | V25: =SUM(S25:T26)-U25 -> 687.04
B26: 9 | D26: =D25 -> Калашников В.В. | E26: Ночь (Т2) | F26: =Arhive!C18 -> 2710.89 | G26: =Arhive!D18 -> 2698.33 | H26: =F26-G26 -> 12.56 | I26: =IF(H26=0,0,H26*100/(H26+H25)) -> 35.967927 | J26: =IF((H25+H26)>150,IF(H25=0,0,H26*100/(H25+H26)*150/100),H26) -> 12.56 | K26: =IF(H26+H25<600,H26-J26,450*(IF(H26=0,0,H26*100/(H26+H25)))/100) -> 0 | L26: =H26-K26-J26 -> 0 | M26: 3.52 | N26: 4.21 | O26: 6.99 | P26: =IF(H26<J26,H26*M26,J26*M26) -> 44.2112 | Q26: =IF(K26<0,0,K26*N26) -> 0 | R26: =IF(L26<0,0,L26*O26) -> 0
B27: =Arhive!A19 -> 10 | C27: =Arhive!G19 -> 8 | D27: =Arhive!B19 -> Картира Я.А. | E27: День (Т1) | F27: =Arhive!C19 -> 5042.34 | G27: =Arhive!D19 -> 4913.53 | H27: =F27-G27 -> 128.81 | I27: =IF(H27=0,0,H27*100/(H27+H28)) -> 64.930941 | J27: =IF((H27+H28)>150,IF(H27=0,0,H27*100/(H27+H28)*150/100),H27) -> 97.396411 | K27: =IF(H27+H28<600,H27-J27,450*(IF(H27=0,0,H27*100/(H27+H28)))/100) -> 31.413589 | L27: =H27-J27-K27 -> 0 | M27: 5.05 | N27: 5.47 | O27: 9.4 | P27: =IF(H27<J27,H27*M27,J27*M27) -> 491.85188 | Q27: =IF(K27<0,0,K27*N27) -> 171.83233 | R27: =IF(L27<0,0,L27*O27) -> 0 | S27: =ROUND(SUM(P27:R28),2) -> 920.28 | T27: =Arhive!E19 -> 1205.5 | U27: =Arhive!F19 -> 0 | V27: =SUM(S27:T28)-U27 -> 2125.78
B28: 10 | D28: =D27 -> Картира Я.А. | E28: Ночь (Т2) | F28: =Arhive!C20 -> 2208.45 | G28: =Arhive!D20 -> 2138.88 | H28: =F28-G28 -> 69.57 | I28: =IF(H28=0,0,H28*100/(H28+H27)) -> 35.069059 | J28: =IF((H27+H28)>150,IF(H27=0,0,H28*100/(H27+H28)*150/100),H28) -> 52.603589 | K28: =IF(H28+H27<600,H28-J28,450*(IF(H28=0,0,H28*100/(H28+H27)))/100) -> 16.966411 | L28: =H28-K28-J28 -> 0 | M28: 3.52 | N28: 4.21 | O28: 6.99 | P28: =IF(H28<J28,H28*M28,J28*M28) -> 185.16463 | Q28: =IF(K28<0,0,K28*N28) -> 71.42859 | R28: =IF(L28<0,0,L28*O28) -> 0
B29: =Arhive!A21 -> 11 | C29: =Arhive!G21 -> 36 | D29: =Arhive!B21 -> Касьяненко А.А. | E29: День (Т1) | F29: =Arhive!C21 -> 24123.17 | G29: =Arhive!D21 -> 23923.71 | H29: =F29-G29 -> 199.46 | I29: =IF(H29=0,0,H29*100/(H29+H30)) -> 74.833046 | J29: =IF((H29+H30)>150,IF(H29=0,0,H29*100/(H29+H30)*150/100),H29) -> 112.24957 | K29: =IF(H29+H30<600,H29-J29,450*(IF(H29=0,0,H29*100/(H29+H30)))/100) -> 87.210431 | L29: =H29-J29-K29 -> 0 | M29: 5.05 | N29: 5.47 | O29: 9.4 | P29: =IF(H29<J29,H29*M29,J29*M29) -> 566.86032 | Q29: =IF(K29<0,0,K29*N29) -> 477.04106 | R29: =IF(L29<0,0,L29*O29) -> 0 | S29: =ROUND(SUM(P29:R30),2) -> 1300.26 | T29: =Arhive!E21 -> -53.74 | U29: =Arhive!F21 -> 1310 | V29: =SUM(S29:T30)-U29 -> -63.48
B30: 11 | D30: =D29 -> Касьяненко А.А. | E30: Ночь (Т2) | F30: =Arhive!C22 -> 8324.13 | G30: =Arhive!D22 -> 8257.05 | H30: =F30-G30 -> 67.08 | I30: =IF(H30=0,0,H30*100/(H30+H29)) -> 25.166954 | J30: =IF((H29+H30)>150,IF(H29=0,0,H30*100/(H29+H30)*150/100),H30) -> 37.750431 | K30: =IF(H30+H29<600,H30-J30,450*(IF(H30=0,0,H30*100/(H30+H29)))/100) -> 29.329569 | L30: =H30-K30-J30 -> 0 | M30: 3.52 | N30: 4.21 | O30: 6.99 | P30: =IF(H30<J30,H30*M30,J30*M30) -> 132.88152 | Q30: =IF(K30<0,0,K30*N30) -> 123.47748 | R30: =IF(L30<0,0,L30*O30) -> 0
B31: =Arhive!A23 -> 12 | C31: =Arhive!G23 -> 18 | D31: =Arhive!B23 -> Ким Т.В. | E31: День (Т1) | F31: =Arhive!C23 -> 15245.87 | G31: =Arhive!D23 -> 14438.65 | H31: =F31-G31 -> 807.22 | I31: =IF(H31=0,0,H31*100/(H31+H32)) -> 78.011868 | J31: =IF((H31+H32)>150,IF(H31=0,0,H31*100/(H31+H32)*150/100),H31) -> 117.0178 | K31: =IF(H31+H32<600,H31-J31,450*(IF(H31=0,0,H31*100/(H31+H32)))/100) -> 351.0534 | L31: =H31-J31-K31 -> 339.14879 | M31: 5.05 | N31: 5.47 | O31: 9.4 | P31: =IF(H31<J31,H31*M31,J31*M31) -> 590.9399 | Q31: =IF(K31<0,0,K31*N31) -> 1920.2621 | R31: =IF(L31<0,0,L31*O31) -> 3187.9987 | S31: =ROUND(SUM(P31:R32),2) -> 6900.05 | T31: =Arhive!E23 -> 0 | U31: =Arhive!F23 -> 0 | V31: =SUM(S31:T32)-U31 -> 6900.05
B32: 8 | D32: =D31 -> Ким Т.В. | E32: Ночь (Т2) | F32: =Arhive!C24 -> 4359.82 | G32: =Arhive!D24 -> 4132.3 | H32: =F32-G32 -> 227.52 | I32: =IF(H32=0,0,H32*100/(H32+H31)) -> 21.988132 | J32: =IF((H31+H32)>150,IF(H31=0,0,H32*100/(H31+H32)*150/100),H32) -> 32.982198 | K32: =IF(H32+H31<600,H32-J32,450*(IF(H32=0,0,H32*100/(H32+H31)))/100) -> 98.946595 | L32: =H32-K32-J32 -> 95.591206 | M32: 3.52 | N32: 4.21 | O32: 6.99 | P32: =IF(H32<J32,H32*M32,J32*M32) -> 116.09734 | Q32: =IF(K32<0,0,K32*N32) -> 416.56517 | R32: =IF(L32<0,0,L32*O32) -> 668.18253
B33: =Arhive!A25 -> 13 | C33: =Arhive!G25 -> 2 | D33: =Arhive!B25 -> Клокова Е.В. | E33: День (Т1) | F33: =Arhive!C25 -> 16096.2 | G33: =Arhive!D25 -> 15843.36 | H33: =F33-G33 -> 252.84 | I33: =IF(H33=0,0,H33*100/(H33+H34)) -> 67.694779 | J33: =IF((H33+H34)>150,IF(H33=0,0,H33*100/(H33+H34)*150/100),H33) -> 101.54217 | K33: =IF(H33+H34<600,H33-J33,450*(IF(H33=0,0,H33*100/(H33+H34)))/100) -> 151.29783 | L33: =H33-J33-K33 -> 0 | M33: 5.05 | N33: 5.47 | O33: 9.4 | P33: =IF(H33<J33,H33*M33,J33*M33) -> 512.78795 | Q33: =IF(K33<0,0,K33*N33) -> 827.59914 | R33: =IF(L33<0,0,L33*O33) -> 0 | S33: =ROUND(SUM(P33:R34),2) -> 1814.93 | T33: =Arhive!E25 -> 2920.69 | U33: =Arhive!F25 -> 3000 | V33: =SUM(S33:T34)-U33 -> 1735.62
B34: 9 | D34: =D33 -> Клокова Е.В. | E34: Ночь (Т2) | F34: =Arhive!C26 -> 6602.25 | G34: =Arhive!D26 -> 6481.59 | H34: =F34-G34 -> 120.66 | I34: =IF(H34=0,0,H34*100/(H34+H33)) -> 32.305221 | J34: =IF((H33+H34)>150,IF(H33=0,0,H34*100/(H33+H34)*150/100),H34) -> 48.457831 | K34: =IF(H34+H33<600,H34-J34,450*(IF(H34=0,0,H34*100/(H34+H33)))/100) -> 72.202169 | L34: =H34-K34-J34 -> 0 | M34: 3.52 | N34: 4.21 | O34: 6.99 | P34: =IF(H34<J34,H34*M34,J34*M34) -> 170.57157 | Q34: =IF(K34<0,0,K34*N34) -> 303.97113 | R34: =IF(L34<0,0,L34*O34) -> 0
B35: =Arhive!A27 -> 14 | C35: =Arhive!G27 -> 9 | D35: =Arhive!B27 -> Коваленко Р.Т. | E35: День (Т1) | F35: =Arhive!C27 -> 10.31 | G35: =Arhive!D27 -> 8.35 | H35: =F35-G35 -> 1.96 | I35: =IF(H35=0,0,H35*100/(H35+H36)) -> 100 | J35: =IF((H35+H36)>150,IF(H35=0,0,H35*100/(H35+H36)*150/100),H35) -> 1.96 | K35: =IF(H35+H36<600,H35-J35,450*(IF(H35=0,0,H35*100/(H35+H36)))/100) -> 0 | L35: =H35-J35-K35 -> 0 | M35: 5.05 | N35: 5.47 | O35: 9.4 | P35: =IF(H35<J35,H35*M35,J35*M35) -> 9.898 | Q35: =IF(K35<0,0,K35*N35) -> 0 | R35: =IF(L35<0,0,L35*O35) -> 0 | S35: =ROUND(SUM(P35:R36),2) -> 9.9 | T35: =Arhive!E27 -> -63.18 | U35: =Arhive!F27 -> 100 | V35: =SUM(S35:T36)-U35 -> -153.28
B36: 10 | D36: =D35 -> Коваленко Р.Т. | E36: Ночь (Т2) | F36: =Arhive!C28 -> 0 | G36: =Arhive!D28 -> 0 | H36: =F36-G36 -> 0 | I36: =IF(H36=0,0,H36*100/(H36+H35)) -> 0 | J36: =IF((H35+H36)>150,IF(H35=0,0,H36*100/(H35+H36)*150/100),H36) -> 0 | K36: =IF(H36+H35<600,H36-J36,450*(IF(H36=0,0,H36*100/(H36+H35)))/100) -> 0 | L36: =H36-K36-J36 -> 0 | M36: 3.52 | N36: 4.21 | O36: 6.99 | P36: =IF(H36<J36,H36*M36,J36*M36) -> 0 | Q36: =IF(K36<0,0,K36*N36) -> 0 | R36: =IF(L36<0,0,L36*O36) -> 0
B37: =Arhive!A29 -> 15 | C37: =Arhive!G29 -> 15 | D37: =Arhive!B29 -> Кралькина И.А. | E37: День (Т1) | F37: =Arhive!C29 -> 140791.9 | G37: =Arhive!D29 -> 139337.75 | H37: =F37-G37 -> 1454.15 | I37: =IF(H37=0,0,H37*100/(H37+H38)) -> 71.431378 | J37: =IF((H37+H38)>150,IF(H37=0,0,H37*100/(H37+H38)*150/100),H37) -> 107.14707 | K37: =IF(H37+H38<600,H37-J37,450*(IF(H37=0,0,H37*100/(H37+H38)))/100) -> 321.4412 | L37: =H37-J37-K37 -> 1025.5617 | M37: 5.05 | N37: 5.47 | O37: 9.4 | P37: =IF(H37<J37,H37*M37,J37*M37) -> 541.09269 | Q37: =IF(K37<0,0,K37*N37) -> 1758.2834 | R37: =IF(L37<0,0,L37*O37) -> 9640.2803 | S37: =ROUND(SUM(P37:R38),2) -> 15498.81 | T37: =Arhive!E29 -> 16847.63 | U37: =Arhive!F29 -> 16850 | V37: =SUM(S37:T38)-U37 -> 15496.44
B38: 11 | D38: =D37 -> Кралькина И.А. | E38: Ночь (Т2) | F38: =Arhive!C30 -> 52726.58 | G38: =Arhive!D30 -> 52145 | H38: =F38-G38 -> 581.58 | I38: =IF(H38=0,0,H38*100/(H38+H37)) -> 28.568622 | J38: =IF((H37+H38)>150,IF(H37=0,0,H38*100/(H37+H38)*150/100),H38) -> 42.852932 | K38: =IF(H38+H37<600,H38-J38,450*(IF(H38=0,0,H38*100/(H38+H37)))/100) -> 128.5588 | L38: =H38-K38-J38 -> 410.16827 | M38: 3.52 | N38: 4.21 | O38: 6.99 | P38: =IF(H38<J38,H38*M38,J38*M38) -> 150.84232 | Q38: =IF(K38<0,0,K38*N38) -> 541.23254 | R38: =IF(L38<0,0,L38*O38) -> 2867.0762
B39: =Arhive!A31 -> 16 | C39: =Arhive!G31 -> 41 | D39: =Arhive!B31 -> Кудряшов Ю.Ю. | E39: День (Т1) | F39: =Arhive!C31 -> 11353.14 | G39: =Arhive!D31 -> 11109.4 | H39: =F39-G39 -> 243.74 | I39: =IF(H39=0,0,H39*100/(H39+H40)) -> 76.187797 | J39: =IF((H39+H40)>150,IF(H39=0,0,H39*100/(H39+H40)*150/100),H39) -> 114.2817 | K39: =IF(H39+H40<600,H39-J39,450*(IF(H39=0,0,H39*100/(H39+H40)))/100) -> 129.4583 | L39: =H39-J39-K39 -> 0 | M39: 5.05 | N39: 5.47 | O39: 9.4 | P39: =IF(H39<J39,H39*M39,J39*M39) -> 577.12256 | Q39: =IF(K39<0,0,K39*N39) -> 708.13693 | R39: =IF(L39<0,0,L39*O39) -> 0 | S39: =ROUND(SUM(P39:R40),2) -> 1581.33 | T39: =Arhive!E31 -> 4352.1 | U39: =Arhive!F31 -> 916.75 | V39: =SUM(S39:T40)-U39 -> 5016.68
B40: 12 | D40: =D39 -> Кудряшов Ю.Ю. | E40: Ночь (Т2) | F40: =Arhive!C32 -> 3589.45 | G40: =Arhive!D32 -> 3513.27 | H40: =F40-G40 -> 76.18 | I40: =IF(H40=0,0,H40*100/(H40+H39)) -> 23.812203 | J40: =IF((H39+H40)>150,IF(H39=0,0,H40*100/(H39+H40)*150/100),H40) -> 35.718305 | K40: =IF(H40+H39<600,H40-J40,450*(IF(H40=0,0,H40*100/(H40+H39)))/100) -> 40.461695 | L40: =H40-K40-J40 -> 0 | M40: 3.52 | N40: 4.21 | O40: 6.99 | P40: =IF(H40<J40,H40*M40,J40*M40) -> 125.72843 | Q40: =IF(K40<0,0,K40*N40) -> 170.34374 | R40: =IF(L40<0,0,L40*O40) -> 0
B41: =Arhive!A33 -> 17 | C41: =Arhive!G33 -> 42 | D41: =Arhive!B33 -> Курашин А.П. | E41: Тариф 1 | F41: =Arhive!C33 -> 72.2 | G41: =Arhive!D33 -> 67.7 | H41: =F41-G41 -> 4.5 | I41: =IF(H41=0,0,H44*100/H41) -> 382.44444 | J41: =IF(H41>150,IF(H41=0,0,H41*100/H41*150/100),H41) -> 4.5 | K41: =IF(H41<600,H41-J41,450*(IF(H41=0,0,H41*100/H41))/100) -> 0 | L41: =H41-J41-K41 -> 0 | M41: 5.05 | N41: 5.47 | O41: 9.4 | P41: =IF(H41<J41,H41*M41,J41*M41) -> 22.725 | Q41: =IF(K41<0,0,K41*N41) -> 0 | R41: =IF(L41<0,0,L41*O41) -> 0 | S41: =ROUND(SUM(P41:R41),2) -> 22.73 | T41: =Arhive!E33 -> -268.98 | U41: =Arhive!F33 -> 0 | V41: =SUM(S41:T41)-U41 -> -246.25
...
